<?xml version="1.0"?>

<robot name="rover">
  <link name="chassis">
    <inertial>
      <origin xyz="0 0 0" />
      <mass value="5.0" />
      <inertia  ixx="1.0" ixy="0.0"  ixz="0.0"  iyy="1.0"  iyz="0.0"  izz="1" />
    </inertial>
    <visual>
      <origin xyz="0 0 0.2"/>
      <geometry>
        <mesh filename="package://rover_gazebo/models/rover/3dmodels/platforma_nieruchome.dae" scale="1.0 1.0 1.0"/>
      </geometry>
    </visual>
    <collision>
      <origin xyz="0 0 0.2"/>
      <geometry>
        <mesh filename="package://rover_gazebo/models/rover/3dmodels/platforma_nieruchome.dae" scale="1.0 1.0 1.0"/>
      </geometry>
    </collision>
  </link>

  <link name="imu_link">
    <inertial>
      <origin xyz="0 0 0" />
      <mass value="0.1" />
      <inertia  ixx="1.0" ixy="0.0"  ixz="0.0"  iyy="1.0"  iyz="0.0"  izz="1" />
    </inertial>
    <visual>
      <origin xyz="0  0  0"/>
      <geometry>
          <box size=".04 .02 .01"/>
      </geometry>
    </visual>
    <collision>
      <origin xyz="0  0  0"/>
      <geometry>
        <box size=".04 .02 .01"/>
      </geometry>
    </collision>
  </link>

  <link name="camera_link">
    <inertial>
      <origin xyz="0 0 0" />
      <mass value="0.1" />
      <inertia  ixx="1.0" ixy="0.0"  ixz="0.0"  iyy="1.0"  iyz="0.0"  izz="1" />
    </inertial>
    <visual>
      <origin xyz="0  0  0"/>
      <geometry>
          <box size=".04 .02 .01"/>
      </geometry>
    </visual>
    <collision>
      <origin xyz="0  0  0"/>
      <geometry>
        <box size=".04 .02 .01"/>
      </geometry>
    </collision>
  </link>

  <link name="lidar_link">
    <inertial>
      <origin xyz="0 0 0" />
      <mass value="0.1" />
      <inertia  ixx="1.0" ixy="0.0"  ixz="0.0"  iyy="1.0"  iyz="0.0"  izz="1" />
    </inertial>
    <visual>
      <origin xyz="0  0  0"/>
      <geometry>
          <box size=".04 .02 .01"/>
      </geometry>
    </visual>
    <collision>
      <origin xyz="0  0  0"/>
      <geometry>
        <box size=".04 .02 .01"/>
      </geometry>
    </collision>
  </link>





  <link name="left_steer">
    <inertial>
      <origin xyz="0 0 0" />
      <mass value=".2" />
      <inertia  ixx="1.0" ixy="0.0"  ixz="0.0"  iyy="1.0"  iyz="0.0"  izz="1" />
    </inertial>
    <visual>
      <origin xyz="-0.32525  0.30404 -0.18389"/>
      <geometry>
        <mesh filename="package://rover_gazebo/models/rover/3dmodels/platforma_lewe_dwa.dae" scale="1.0 1.0 1.0"/>
      </geometry>
    </visual>
    <collision>
      <origin xyz="-0.32525  0.30404 -0.18389"/>
      <geometry>
        <mesh filename="package://rover_gazebo/models/rover/3dmodels/platforma_lewe_dwa.dae" scale="1.0 1.0 1.0"/>
      </geometry>
    </collision>
  </link>

  <link name="right_steer">
    <inertial>
      <origin xyz="0 0 0" />
      <mass value=".2" />
      <inertia  ixx="1.0" ixy="0.0"  ixz="0.0"  iyy="1.0"  iyz="0.0"  izz="1" />
    </inertial>
    <visual>
      <origin xyz="-0.32525 -0.30404 -0.18389"/>
      <geometry>
        <mesh filename="package://rover_gazebo/models/rover/3dmodels/platforma_prawe_dwa.dae" scale="1.0 1.0 1.0"/>
      </geometry>
    </visual>
    <collision>
      <origin xyz="-0.32525 -0.30404 -0.18389"/>
      <geometry>
        <mesh filename="package://rover_gazebo/models/rover/3dmodels/platforma_prawe_dwa.dae" scale="1.0 1.0 1.0"/>
      </geometry>
    </collision>
  </link>


  <link name="left_wheel_1">
    <inertial>
      <origin xyz="0 0 0" />
      <mass value=".2" />
      <inertia  ixx="0.0009" ixy="0.0"  ixz="0.0"  iyy="0.0009"  iyz="0.0"  izz="0.001" />
    </inertial>
    <visual>
      <origin xyz="0.41492  0.346    0.04176"/>
      <geometry>
        <mesh filename="package://rover_gazebo/models/rover/3dmodels/platforma_kolo_lewe1.dae" scale="1.0 1.0 1.0"/>
      </geometry>
    </visual>
    <collision>
      <origin xyz="0.41492  0.346    0.04176"/>
      <geometry>
        <mesh filename="package://rover_gazebo/models/rover/3dmodels/platforma_kolo_lewe1.dae" scale="1.0 1.0 1.0"/>
      </geometry>
    </collision>
  </link>


  <link name="left_wheel_2">
    <inertial>
      <origin xyz="0 0 0" />
      <mass value=".2" />
      <inertia  ixx="0.0009" ixy="0.0"  ixz="0.0"  iyy="0.0009"  iyz="0.0"  izz="0.001" />
    </inertial>
    <visual>
      <origin xyz="-0.0742   0.346   -0.00293"/>
      <geometry>
        <mesh filename="package://rover_gazebo/models/rover/3dmodels/platforma_kolo_lewe2.dae" scale="1.0 1.0 1.0"/>
      </geometry>
    </visual>
    <collision>
      <origin xyz="-0.0742   0.346   -0.00293"/>
      <geometry>
        <mesh filename="package://rover_gazebo/models/rover/3dmodels/platforma_kolo_lewe2.dae" scale="1.0 1.0 1.0"/>
      </geometry>
    </collision>
  </link>

  <link name="left_wheel_3">
    <inertial>
      <origin xyz="0 0 0" />
      <mass value=".2" />
      <inertia  ixx="0.0009" ixy="0.0"  ixz="0.0"  iyy="0.0009"  iyz="0.0"  izz="0.001" />
    </inertial>
    <visual>
      <origin xyz="-5.74160000e-01   3.46000000e-01  -9.00000000e-05"/>
      <geometry>
        <mesh filename="package://rover_gazebo/models/rover/3dmodels/platforma_kolo_lewe3.dae" scale="1.0 1.0 1.0"/>
      </geometry>
    </visual>
    <collision>
      <origin xyz="-5.74160000e-01   3.46000000e-01  -9.00000000e-05"/>
      <geometry>
        <mesh filename="package://rover_gazebo/models/rover/3dmodels/platforma_kolo_lewe3.dae" scale="1.0 1.0 1.0"/>
      </geometry>
    </collision>
  </link>

  <link name="right_wheel_1">
    <inertial>
      <origin xyz="0 0 0" />
      <mass value=".2" />
      <inertia  ixx="0.0009" ixy="0.0"  ixz="0.0"  iyy="0.0009"  iyz="0.0"  izz="0.001" />
    </inertial>
    <visual>
      <origin xyz="0.41492 -0.346    0.04176"/>
      <geometry>
        <mesh filename="package://rover_gazebo/models/rover/3dmodels/platforma_kolo_prawe1.dae" scale="1.0 1.0 1.0"/>
      </geometry>
    </visual>
    <collision>
      <origin xyz="0.41492 -0.346    0.04176"/>
      <geometry>
        <mesh filename="package://rover_gazebo/models/rover/3dmodels/platforma_kolo_prawe1.dae" scale="1.0 1.0 1.0"/>
      </geometry>
    </collision>
  </link>


  <link name="right_wheel_2">
    <inertial>
      <origin xyz="0 0 0" />
      <mass value=".2" />
      <inertia  ixx="0.0009" ixy="0.0"  ixz="0.0"  iyy="0.0009"  iyz="0.0"  izz="0.001" />
    </inertial>
    <visual>
      <origin xyz="-0.0742   -0.346   -0.00293"/>
      <geometry>
        <mesh filename="package://rover_gazebo/models/rover/3dmodels/platforma_kolo_prawe2.dae" scale="1.0 1.0 1.0"/>
      </geometry>
    </visual>
    <collision>
      <origin xyz="-0.0742   -0.346   -0.00293"/>
      <geometry>
        <mesh filename="package://rover_gazebo/models/rover/3dmodels/platforma_kolo_prawe2.dae" scale="1.0 1.0 1.0"/>
      </geometry>
    </collision>
  </link>

  <link name="right_wheel_3">
    <inertial>
      <origin xyz="0 0 0" />
      <mass value=".2" />
      <inertia  ixx="0.0009" ixy="0.0"  ixz="0.0"  iyy="0.0009"  iyz="0.0"  izz="0.001" />
    </inertial>
    <visual>
      <origin xyz="-5.74160000e-01   -3.46000000e-01  -9.00000000e-05"/>
      <geometry>
        <mesh filename="package://rover_gazebo/models/rover/3dmodels/platforma_kolo_prawe3.dae" scale="1.0 1.0 1.0"/>
      </geometry>
    </visual>
    <collision>
      <origin xyz="-5.74160000e-01   -3.46000000e-01  -9.00000000e-05"/>
      <geometry>
        <mesh filename="package://rover_gazebo/models/rover/3dmodels/platforma_kolo_prawe3.dae" scale="1.0 1.0 1.0"/>
      </geometry>
    </collision>
  </link>

  <joint name="imu_joint" type="fixed">
    <parent link="chassis"/>
    <child link="imu_link"/>
    <origin rpy="0  0  0" xyz="0       0       0.61032"/>
    <axis xyz="0 0  0"/>
    <limit effort="0.0" lower="0" upper="0" velocity="0.0"/>
  </joint>


  <joint name="camera_joint" type="fixed">
    <parent link="chassis"/>
    <child link="camera_link"/>
    <origin rpy="0  0.0873  3.14159265" xyz="-0.28996  0       0.61032"/>
    <axis xyz="0 0  0"/>
    <limit effort="0.0" lower="0" upper="0" velocity="0.0"/>
  </joint>

  <joint name="lidar_joint" type="fixed">
    <parent link="chassis"/>
    <child link="lidar_link"/>
    <origin rpy="0  0.1222  3.14159265"  xyz="-0.28996       0       0.63032"/>
    <axis xyz="0 0  0"/>
    <limit effort="0.0" lower="0" upper="0" velocity="0.0"/>
  </joint>



  <joint name="left_steer_hinge" type="continuous">
    <parent link="chassis"/>
    <child link="left_steer"/>
    <origin rpy="0  0  0" xyz="0.32525 -0.30404  0.38389"/>
    <axis xyz="0 -1  0"/>
    <limit effort="0.0" lower="-0.5" upper="1.0" velocity="0.0"/>
  </joint>

  <joint name="right_steer_hinge" type="continuous">
    <parent link="chassis"/>
    <child link="right_steer"/>
    <origin rpy="0  0  0" xyz="0.32525  0.30404  0.38389"/>
    <axis xyz="0 1  0"/>
    <limit effort="0.0" lower="-0.5" upper="1.0" velocity="0.0"/>
  </joint>

  <joint name="left_wheel_1_hinge" type="continuous">
    <parent link="chassis"/>
    <child link="left_wheel_1"/>
    <origin rpy="0  0  0" xyz="-0.41492 -0.346    0.15824"/>
    <axis xyz="0 -1  0"/>
    <limit effort="0" lower="-9999999999999" upper="9999999999999" velocity="0"/>
  </joint>

  <joint name="left_wheel_2_hinge" type="continuous">
    <parent link="left_steer"/>
    <child link="left_wheel_2"/>
    <origin rpy="0  0  0" xyz="-0.25105 -0.04195 -0.18095"/>
    <axis xyz="0 -1  0"/>
    <limit effort="0" lower="-9999999999999" upper="9999999999999" velocity="0"/>
  </joint>

  <joint name="left_wheel_3_hinge" type="continuous">
    <parent link="left_steer"/>
    <child link="left_wheel_3"/>
    <origin rpy="0  0  0" xyz="0.24891 -0.04195 -0.18379"/>
    <axis xyz="0 1  0"/>
    <limit effort="0" lower="-9999999999999" upper="9999999999999" velocity="0"/>
  </joint>

  <joint name="right_wheel_1_hinge" type="continuous">
    <parent link="chassis"/>
    <child link="right_wheel_1"/>
    <origin rpy="0  0  0" xyz="-0.41492 0.346    0.15824"/>
    <axis xyz="0 1  0"/>
    <limit effort="0" lower="-9999999999999" upper="9999999999999" velocity="0"/>
  </joint>

  <joint name="right_wheel_2_hinge" type="continuous">
    <parent link="right_steer"/>
    <child link="right_wheel_2"/>
    <origin rpy="0  0  0" xyz="-0.25105 0.04195 -0.18095"/>
    <axis xyz="0 1  0"/>
    <limit effort="0" lower="-9999999999999" upper="9999999999999" velocity="0"/>
  </joint>

  <joint name="right_wheel_3_hinge" type="continuous">
    <parent link="right_steer"/>
    <child link="right_wheel_3"/>
    <origin rpy="0  0  0" xyz="0.24891 0.04195 -0.18379"/>
    <axis xyz="0 1  0"/>
    <limit effort="0" lower="-9999999999999" upper="9999999999999" velocity="0"/>
  </joint>


  <gazebo reference ="left_wheel_1">
      <mu1 value="200.0"/>
      <mu2 value="100.0"/>
      <kp value="10000000.0"/>
      <kd value= "1.0"/>
      <material>Gazebo/Black</material>
  </gazebo>
  <gazebo reference ="left_wheel_2">
      <mu1 value="200.0"/>
      <mu2 value="100.0"/>
      <kp value="10000000.0"/>
      <kd value= "1.0"/>
      <material>Gazebo/Black</material>
  </gazebo>
  <gazebo reference ="left_wheel_3">
      <mu1 value="200.0"/>
      <mu2 value="100.0"/>
      <kp value="10000000.0"/>
      <kd value= "1.0"/>
      <material>Gazebo/Black</material>
  </gazebo>
  <gazebo reference ="right_wheel_1">
      <mu1 value="200.0"/>
      <mu2 value="100.0"/>
      <kp value="10000000.0"/>
      <kd value= "1.0"/>
      <material>Gazebo/Black</material>
  </gazebo>
  <gazebo reference ="right_wheel_2">
      <mu1 value="200.0"/>
      <mu2 value="100.0"/>
      <kp value="10000000.0"/>
      <kd value= "1.0"/>
      <material>Gazebo/Black</material>
  </gazebo>
  <gazebo reference ="right_wheel_3">
      <mu1 value="200.0"/>
      <mu2 value="100.0"/>
      <kp value="10000000.0"/>
      <kd value= "1.0"/>
      <material>Gazebo/Black</material>
  </gazebo>



  <gazebo reference="chassis">
    <material>Gazebo/Blue</material>
  </gazebo>


  <gazebo reference="camera_link">
    <sensor name="d_camera" type="depth">
      <pose>-0.28996  0 0.61032 0 0 0</pose>
      <visualize>true</visualize>
      <update_rate>10</update_rate>
      <camera>
        <horizontal_fov>1.047198</horizontal_fov>
        <image>
          <width>640</width>
          <height>480</height>
          <format>R8G8B8</format>
        </image>
        <clip>
          <near>0.05</near>
          <far>3</far>
        </clip>
      </camera>
      <plugin name="d_controller" filename="libgazebo_ros_openni_kinect.so">
        <baseline>0.2</baseline>
        <alwaysOn>true</alwaysOn>
        <updateRate>1.0</updateRate>
        <cameraName>kamera_ir</cameraName>
        <imageTopicName>/kamera/depth/image_raw</imageTopicName>
        <cameraInfoTopicName>/kamera/depth/camera_info</cameraInfoTopicName>
        <depthImageTopicName>/kamera/depth/image_raw</depthImageTopicName>
        <depthImageInfoTopicName>/kamera/depth/camera_info</depthImageInfoTopicName>
        <pointCloudTopicName>/kamera/depth/points</pointCloudTopicName>
        <frameName>image</frameName>
        <pointCloudCutoff>0.5</pointCloudCutoff>
        <pointCloudCutoffMax>3.0</pointCloudCutoffMax>
        <distortionK1>0.00000001</distortionK1>
        <distortionK2>0.00000001</distortionK2>
        <distortionK3>0.00000001</distortionK3>
        <distortionT1>0.00000001</distortionT1>
        <distortionT2>0.00000001</distortionT2>
        <CxPrime>0</CxPrime>
        <Cx>0</Cx>
        <Cy>0</Cy>
        <focalLength>0</focalLength>
        <hackBaseline>0</hackBaseline>
      </plugin>
    </sensor>
  </gazebo>


  <gazebo reference="lidar_link">
    <sensor type="gpu_ray" name="head_hokuyo_sensor">
      <pose>0 0 0.62032 0 0 0</pose>
      <visualize>true</visualize>
      <update_rate>40</update_rate>
      <ray>
        <scan>
          <horizontal>
            <samples>720</samples>
            <resolution>1</resolution>
            <min_angle>-1.570796</min_angle>
            <max_angle>1.570796</max_angle>
          </horizontal>
        </scan>
        <range>
          <min>0.10</min>
          <max>30.0</max>
          <resolution>0.01</resolution>
        </range>
        <noise>
          <type>gaussian</type>
          <!-- Noise parameters based on published spec for Hokuyo laser
               achieving "+-30mm" accuracy at range < 10m.  A mean of 0.0m and
               stddev of 0.01m will put 99.7% of samples within 0.03m of the true
               reading. -->
          <mean>0.0</mean>
          <stddev>0.01</stddev>
        </noise>
      </ray>
      <plugin name="gazebo_ros_head_hokuyo_controller" filename="libgazebo_ros_gpu_laser.so">
        <topicName>/rover/laser/scan</topicName>
        <frameName>hokuyo_link</frameName>
      </plugin>
    </sensor>
  </gazebo>

  <gazebo reference="imu_link">
      <gravity>true</gravity>
      <sensor name="imu_sensor" type="imu">
        <always_on>true</always_on>
        <update_rate>100</update_rate>
        <visualize>true</visualize>
        <topic>__default_topic__</topic>
        <plugin filename="libgazebo_ros_imu_sensor.so" name="imu_plugin">
          <topicName>rover/imu</topicName>
          <bodyName>imu_link</bodyName>
          <updateRateHZ>10.0</updateRateHZ>
          <gaussianNoise>0.0</gaussianNoise>
          <xyzOffset>0 0 0</xyzOffset>
          <rpyOffset>0 0 0</rpyOffset>
          <frameName>imu_link</frameName>
        </plugin>
        <pose>0 0 0 0 0 0</pose>
      </sensor>
    </gazebo>
<!--
    <gazebo>
        <plugin name="gazebo_ros_control" filename="libgazebo_ros_control.so">
          <robotNamespace>/rover</robotNamespace>
          <legacyModeNS>true</legacyModeNS>
        </plugin>
      </gazebo>


   <transmission name="left_steer_trans">
        <type>transmission_interface/SimpleTransmission</type>
        <actuator name="motor7">
        </actuator>
        <joint name="left_steer_hinge">
            <hardwareInterface>hardware_interface/VelocityJointInterface</hardwareInterface>
        </joint>
      </transmission>

      <transmission name="right_steer_trans">
        <type>transmission_interface/SimpleTransmission</type>
        <actuator name="motor8">
        </actuator>
        <joint name="right_steer_hinge">
            <hardwareInterface>hardware_interface/VelocityJointInterface</hardwareInterface>
        </joint>
      </transmission>




  <transmission name="left_wheel_1_trans">
        <type>transmission_interface/SimpleTransmission</type>
        <actuator name="motor1">
          <hardwareInterface>EffortJointInterface</hardwareInterface>
          <mechanicalReduction>1</mechanicalReduction>
        </actuator>
        <joint name="left_wheel_1_hinge">
          <hardwareInterface>hardware_interface/VelocityJointInterface</hardwareInterface>
        </joint>
      </transmission>

      <transmission name="left_wheel_2_trans">
        <type>transmission_interface/SimpleTransmission</type>
        <actuator name="motor2">
          <hardwareInterface>EffortJointInterface</hardwareInterface>
          <mechanicalReduction>1</mechanicalReduction>
        </actuator>
        <joint name="left_wheel_2_hinge">
          <hardwareInterface>hardware_interface/VelocityJointInterface</hardwareInterface>
        </joint>
      </transmission>
      <transmission name="left_wheel_3_trans">
        <type>transmission_interface/SimpleTransmission</type>
        <actuator name="motor3">
          <hardwareInterface>EffortJointInterface</hardwareInterface>
          <mechanicalReduction>1</mechanicalReduction>
        </actuator>
        <joint name="left_wheel_3_hinge">
          <hardwareInterface>hardware_interface/VelocityJointInterface</hardwareInterface>
        </joint>
      </transmission>

      <transmission name="right_wheel_1_trans">
        <type>transmission_interface/SimpleTransmission</type>
        <actuator name="motor4">
          <hardwareInterface>EffortJointInterface</hardwareInterface>
          <mechanicalReduction>1</mechanicalReduction>
        </actuator>
        <joint name="right_wheel_1_hinge">
          <hardwareInterface>hardware_interface/VelocityJointInterface</hardwareInterface>
        </joint>
      </transmission>
      <transmission name="right_wheel_2_trans">
        <type>transmission_interface/SimpleTransmission</type>
        <actuator name="motor5">
          <hardwareInterface>EffortJointInterface</hardwareInterface>
          <mechanicalReduction>1</mechanicalReduction>
        </actuator>
        <joint name="right_wheel_2_hinge">
          <hardwareInterface>hardware_interface/VelocityJointInterface</hardwareInterface>
        </joint>
      </transmission>
      <transmission name="right_wheel_3_trans">
        <type>transmission_interface/SimpleTransmission</type>
        <actuator name="motor6">
          <hardwareInterface>EffortJointInterface</hardwareInterface>
          <mechanicalReduction>1</mechanicalReduction>
        </actuator>
        <joint name="right_wheel_3_hinge">
          <hardwareInterface>hardware_interface/VelocityJointInterface</hardwareInterface>
        </joint>
      </transmission>
-->

<gazebo>
  <plugin name="skid_steer_drive_controller" filename="libgazebo_ros_skid_steer_drive.so">
    <updateRate>50.0</updateRate>
    <robotNamespace>/rover</robotNamespace>
    <leftRearJoint>left_wheel_2_hinge</leftRearJoint>
    <rightRearJoint>right_wheel_2_hinge</rightRearJoint>
    <leftFrontJoint>left_wheel_1_hinge</leftFrontJoint>
    <rightFrontJoint>right_wheel_1_hinge</rightFrontJoint>
    <wheelSeparation>0.692</wheelSeparation>
    <wheelDiameter>0.2034</wheelDiameter>
    <robotBaseFrame>chassis</robotBaseFrame>
    <torque>20</torque>
    <topicName>cmd_vel</topicName>
    <broadcastTF>true</broadcastTF>
  </plugin>
</gazebo>

</robot>
